Workbook

Sheet Reference Matrix
A1: GENERAL INSTRUCTIONS
A2: This workbook contains twelve (12) worksheets to provide supplementary documentation to Annex 4.2. of the Administrative Order No. 25, series of 2011 Inter-Agency Task Force (AO25-IATF) Memorandum Circular No. 2023-1. Performance-Based Bonus (PBB) Focal Persons of State Universities and Colleges (SUCs) are requested to accomplish the appropriate and applicable worksheets. Please do not alter or edit the format of this template. Kindly input all requested information in each worksheet. Indicate the complete name of the institution in Row 1, and provide the links to respective Google Drive Folders in Row 7 of each worksheet. At the end of each worksheet, indicate the requested details of signatories. Kindly upload and submit the completed Summary Sheets (signed PDF and editable Excel file format) in the Government Executive Information System (GEIS) on or before 29 February 2024. The reference matrix below details the definition, formula, documentation, and means of verification for each Output and Outcome Indicator in the 2023 General Appropriations Act for SUCs. Thank you for your kind and usual cooperation.
A4: PROGRAM / INDICATOR | B4: INDICATOR | C4: DEFINITION | D4: FORMULA | E4: REFERENCES / GUIDES | F4: MEANS OF VERIFICATION
A5: HIGHER EDUCATION PROGRAM
A6: OUTCOME | B6: 1. Percentage of first-time licensure exam takers that pass the licensure exams | C6: Ratio of the passers to the total number of takers (1st time) of all board/licensure exams in FY 2023 | D6: Numerator: Total number of passers (1st time) of all board/licensure exams in FY 2023 Denominator: Total number of 1st time takers of all board/licensure exams in FY 2023 | E6: Summary Sheets | F6: 1. PRC/MARINA licensure examination results
A7: OUTCOME | B7: 2. Percentage of graduates (2 years prior) that are employed | C7: Ratio of graduates in FY 2021 who are employed as of FY 2023 to the total number of graduates in FY 2021 | D7: Numerator: Total number of graduates employed as of FY 2023 out of the graduates in FY 2021 (based on adopted Academic calendar) Denominator: Total number of graduates in FY 2021 in all undergraduate programs per campus (based on adopted academic calendar) | E7: Summary Sheets | F7: 1. Graduate tracer study 2. Result of survey of employed from the graduates in the 1st semester of FY 2021-2022, certified by the Registrar 3. Total Enrolment in the 1st Semester of AY 2021-2022, certified by the Registrar
A8: OUTPUT | B8: 1. Percentage of undergraduate students enrolled in CHED-identified and RDC-identified priority programs | C8: Ratio of undergraduate student enollment (1st Sem AY 2023-2024) in CHED identified and RDC-identified priority programs to all other programs | D8: Numerator: Number of students enrolled in CHED- identified and RDC-identified priority programs (1st Sem AY 2023-2024) Denominator: Total number of undergraduate enrollment (1st Sem AY 2023-2024) | E8: References in determining the disciplines/programs identified as priority offerings: a. CMO No. 5, s. 2019 b. CMO No. 10, s. 2021 c. CMO No. 7, s. 2023 d. RDC Resolutions | F8: 1. Duly certified enrollment report for the 1st Semester of AY 2023-2024 per campus 2. Summary of Enrolment by identified priority undergraduate programs, and all other programs per campus 3. CHED-identified priority programs listed in CHED Memorandum Order (CMO) No. 5, s. 2019 and CMO No. 10, s. 2021 4. For programs considered priority outside those identified by CHED, submit certification, resolution from RDC or similar Government Councils, etc.
A9: OUTPUT | B9: 2. Percentage of undergraduate programs with accreditation | C9: Ratio of undergraduate programs with valid accreditation (Level 1 - Level 4 as of December 31, 2023) to all accreditable programs | D9: Numerator: Number of undergraduate programs with Level 1-Level 4 accreditation valid as of December 31, 2023 Denominator: Total number of accreditable undergraduate programs as of December 31, 2023 | E9: Accreditation includes those issued by local and international bodies recognized by CHED; CMO No. 1, s. 2005; AACCUP (Level 1 - Level 4) | F9: 1. Accreditation Certificates 2. List of all undergraduate programs per campus with accreditation (include date of validity) or without accreditation (include reasons for non-accreditation), and indicate year of initial operation of each of the programs being offered
A10: ADVANCED EDUCATION PROGRAM
A11: OUTCOME | B11: 1. Percentage of graduate school faculty engaged in research work applied in any of the following: a) pursuing advanced research degree programs (doctorate degree) or b) actively pursuing within the last three (3) years (investigative research, basic and applied scientific research, policy research, social science research) or c) producing technologies for commercialization or livelihood improvement or d) whose research work resulted in an extension program | C11: Ratio of graduate school faculty engaged in research work to the total number of graduate school faculty. | D11: Numerator: Total number of graduate school faculty with plantilla positions engaged in research work (in any of the enumerated engagements) as of December 31, 2023 Denominator: Total number of graduate school faculty with plantilla positions as of December 31, 2023 | E11: Graduate school faculty: 1. List of graduate school faculty (full time or part time), with academic plantilla positions 2. Personnel Services index of plantilla positions (PSIPOP), with the name of graduate faculty listed in the PSIPOP as proof that faculty memeber can be considered in this indicator | F11: 1. Research work assignment, designations of the graduate school faculty 2. Any proof of involvement in (b) and/or (c) 3. Proof of registration/enrolment in an advance research degree for first year AY 2023-2024 4.List of graduate school faculty with plantilla engaged in research vs all graduate school faculty with plantilla position 5. Notarized MOA with partner community/ies and abstract or research work
A12: OUTPUT | B12: For State Universities: Percentage of graduate students enrolled in research degree programs | C12: Ratio of graduate student enollment (1st Sem AY 2022-2023) in research degree programs to total graduate school enrolment (1st sem AY 2022-2023) Research degree program refers to graduate programs with THESIS or DISSERTATION | D12: Numerator: Number of graduate students enrolled in research degree programs (1st Sem of AY 2023-2024) Denominator: Total number of graduate students enrollment in all graduate programs (1st Sem of AY 2023-2024) | E12: CMO No. 15, s. 2019 | F12: 1. Duly certified enrollment report 2. Summary of Enrolment by research and non-research degree program 3. Curriculum/Course Syllabi
A13: OUTPUT | B13: For State Colleges and Professional Institutes: Percentage of graduate students enrolled in CHED-identified or RDC-identified priority programs | C13: Ratio of graduate student enollment (1st Sem AY 2022-2023) in CHED identified and RDC-identified priority graduate programs to all other graduate programs | D13: Numerator: Graduate student enollment (1st Sem AY 2022-2023) in CHED identified and RDC-identified priority graduate programs Denominator: Total graduate student enollment (1st Sem AY 2022-2023) | E13: References in determining the disciplines/programs identified as priority offerings: a. CMO No. 5, s. 2019 b. CMO No. 10, s. 2021 c. CMO No. 7, s. 2023 d. RDC Resolutions | F13: 1. Duly certified enrollment report 2. Summary of Enrolment by identified priority graduate programs, and all other programs per campus 3. For programs considered priority outside those identified by the CHED, submit certification, resolution from RDC or similar Government Councils, etc.
A14: OUTPUT | B14: 2. Percentage of accredited graduate programs | C14: Ratio of graduate programs with valid accreditation (Level 1 - Level 4 as of December 31, 2023) to all accreditable programs | D14: Numerator: Number of graduate programs with Level 1-Level 4 accreditation valid as of December 31, 2023 Denominator: Total number of accreditable graduate programs as of December 31, 2023 | E14: Accreditation includes those issued by local and international bodies recognized by CHED; AACCUP (Level 1 - Level 4) | F14: 1. Accreditation Certificates 2. List of all graduate programs per campus with or without accreditation (include reasons for non-accreditation), indicate year of initial operation
A15: RESEARCH PROGRAM
A16: OUTCOME | B16: Number of research outputs in the last three years (FY 2021-2023) utilized by the industry or by other beneficiaries | C16: Number of research outputs from FY 2021-2023 utliized by industry or by other beneficiaries | D16: Number of research outputs from FY 2021-2023 utilized by industry or by other beneficiaries in FY 2023 | E16: Utilized by industry or other beneficiaries refers to the adopters/partners/communities, external to the institution | F16: 1. Proof that the research output was utilized by identified stakeholders/beneficiaries 2. MOAs/MOUs 3. Reports with testimonies 4. Certification from industries/beneficiaries on the utilization of research outputs
A17: OUTPUT | B17: 1. Number of research outputs completed within the year | C17: Refers to the total number of completed researches in FY 2023 | D17: Number of completed researches in FY 2023 | E17: Research outputs may comprise any or all of the following: 1. Completed research-based papers; 2. Research-based papers or articles published in journals or international refereed publications that are not in the Beall's List of Predatory Journals; 3. Research-based papers or articles presented in international, national, or regional fora or conferences; 4. Inventions or innovations, methods, composition, or processes as a result of research 5. Models/inventions duly patented and applied for commercial purposes or utilized/adopted for development/production/service provision | F17: 1. Abstracts of research outputs 2. Certificate of completion signed by the Research Director/Vice President for Research
A18: OUTPUT | B18: For State Universities: Percentage of researches published within the year (FY 2023) in internationally-refereed journal | C18: Refers to the ratio of research outputs published in FY 2023 to the total number of completed research outputs from FY 2021 to FY 2023 (to exclude completed research outputs published in 2021 and 2022) | D18: Numerator: Number of research outputs published within FY 2023 in internationally-refereed journal Denominator: Total number of completed research outputs from FY 2021 to FY 2023 (to exclude completed research outputs published in the prior years, 2021 and 2022) | E18: Beall's List of Predatory Journals Documentation on the details of journals to qualify in internationally refereed journals | F18: 1. Photocopy of the journal's title page, and 1st page of the article published
A19: OUTPUT | B19: For State Colleges and Professional Institutes: Percentage of researches presented within the year (FY 2023) in national, regional, and international fora | C19: Refers to the ratio of research outputs presented in FY 2023 to the total number of completed research outputs from FY 2021 to 2023 (to exclude research outputs already presented in 2021 and 2022) | D19: Numerator: Number of research outputs presented within FY 2023 in national, regional and international fora Denominator: Total number of completed research outputs from FY 2021-2023 (to exclude research outputs already presented prior to 2023) | E19: In-house review presentations are not included nor considered as presentations in qualified fora. | F19: 1. Conference proceeding indicating research article presented 2. Program of activities and attendance to the conference 3. Certificate of participation / recognition for presenting the research output
A20: TECHNICAL ADVISORY EXTENSION PROGRAM
A21: OUTCOME | B21: 1. Number of active partnerships with LGUs, industries, NGOs, NGAs, SMEs, and other stakeholders as a result of extension activities. | C21: Number partnerships established by the insitution with the industires, NGOs, NGAs, SMEs and other stakeholder group active as of December 31, 2023 | D21: Number of partnerships established as a result of extension activities | E21: Number partnerships established by the insitution with the industires, NGOs, NGAs, SMEs and other stakeholder group active as of December 31, 2023 | F21: 1. Proof of active partnerships 2. MOAs/MOUs 3. Reports with testimonies 4. Certifications
A22: OUTPUT | B22: 1. Number of trainees weighted by the length of training | C22: Refers to the insitution's total number of participants trained in relation to the corresponding length or duration of training | D22: Target number of trainees weighted by the length of training for FY 2023 | E22: Training hours are weighted as follows: < 8 hrs = 0.5 1 day (8 hours) = 1 2 days (16 hours) = 1.25 3-4 days (24-32 hours) = 1.5 5 days or more (40 hours or more) = 2 | F22: 1. Extension activity reports to include the attendance sheets, specifying the nature and duration of the training 2. Program of the Training Activity
A23: OUTPUT | B23: 2. Number of extension programs organized and supported consistent with the SUC's mandated and priority programs | C23: Refers to the number of extension programs organized by the SUC | D23: Target number of Extension Programs organized in FY 2023 | E23: Unit of analysis: Extension Programs Extension Program: (Reference: CMO 8 s.2010) Extension refers to the act of communicating and transferring knowledge and technology to specific sectors and target clienteles (as distinguished from those enrolled in formal degree programs and course offerings) to enable them to effectively improve production,community and/or institutions, and quality of life at the same time enhance the HEIs academic and research programs Integrated Extension Program SHALL include the following components: 1. Training programs 2. Technical assistance and advisory services 3. Communication/information services 4. Community outreach activities 5. Technology transfer and utilization | F23: 1. List of extension programs approved per mandated and priority programs 2. Program Description
A24: OUTPUT | B24: 3. Percentage of beneficiaries who rate the training course/s as satisfactory or higher in terms of quality and relevance | C24: Ratio of beneficiaries who rated the training course as satisfactory or higher than the total of number of beneficiaries | D24: Numerator: Number of beneficiaries who rated the training course(s) as satisfactory or higher Denominator: Total number of beneficiaries | E24: Rating Scale: 1 (P) = Poor 2 (F) = Fair 3 (S) = Satisfactory 4 (VS) = Very Satisfactory 5 (E) = Excellent | F24: 1. Survey questionnaire and samples of duly accomplished forms 2. Training program including attendance sheets 3. Summary of evaluation by beneficiaries
A25: CUSTODIAL CARE PROGRAM
A26: OUTCOME | B26: 1. Percentage of CCP resident-graduates employed within a year after graduation | C26: Ratio of graduates gainfully employed as of FY 2023 to the total number of CCP residents who graduated in AY 2022-2023 | D26: Numerator: Total number of CCP resident-graduates employed as of FY 2023 Denominator: Total number of CCP resident-graduates in AY 2022-2023 for all programs | F26: 1. Graduate tracer study 2. List/summary of CCP graduates of AY 2022-2023
A27: OUTPUT | B27: 1. Percentage of poor/disadvantaged students (CCP residents) served for non- academic needs | C27: Ratio of CCP students served for non-academic needs to the total number of students | D27: Numerator: Total number CCP students served for non-academic needs for FY 2023 Denominator: Total number of undergraduate students' enrollment for FY 2023 | F27: 1. List of CCP residents approved by management/board 2. Enrolment Report of CCP residents (1st Sem AY 2023-2024) 3. List/Summary of undergraduate enrollment (1st Sem AY 2023-2024)
A28: OUTPUT | B28: 2. Percentage of students (CCP residents) who graduated within the prescribed period | C28: Ratio of CCP students who finished their respective baccalaureate programs within the prescribed timeframe (graduates of 2nd Semester of AY 2022-2023) to the total number of CCP students who are enrolled since AY 2019-2020 | D28: Numerator: Total number of CCP students who graduated in 2nd Semester of AY 2020-2021 Denominator: Total number CCP students' First Year enrolment in the 1st Semester AY 2019-2020 | F28: 1. List of CCP residents enrolled in 1st year AY 2019-2020 2. List of CCP residents who graduated 2nd Sem of AY 2022-2023

Sheet Higher Education (Oc1)
B1: NAME OF INSTITUTION: | C1: (MARINDUQUE STATE COLLEGE)
B2: PROGRAM: | C2: HIGHER EDUCATION PROGRAM
B3: INDICATOR/S: | C3: Outcome Indicator 1: Percentage of first-time licensure exam takers that pass the licensure exams
B4: INSTRUCTIONS: | C4: Kindly fill out Column 1 by listing all undergraduate programs with licensure examination. Please do not abbreviate or shorten program names. In Column 2, list all examination dates for the corresponding programs and input in Column 3 and Column 4 the number of first time takers and first time passers respectively. In Column 5, provide the supporting documentation used in reference to the information in the previous columns. You may also provide links to the scanned copies for easier reference. Computations in the summary bar below is automated. To create additional rows, kindly insert new rows after Row 31.
B5: REFERENCES: | C5: ='Reference Matrix'!$E6 -> Summary Sheets
B6: MEANS OF VERIFICATION: | C6: ='Reference Matrix'!$F6 -> 1. PRC/MARINA licensure examination results
B7: LINK TO GOOGLE DRIVE FOLDER: | C7: (https://drive.google.com/drive/folders/1Zezs1rJYwXox2umra5r2TT9W34aBuL09?usp=drive_link)
A9: SAMPLE
A10: 1 | C10: 2 | D10: 3 | E10: 4 | F10: 5
A11: Undergraduate Program Offered | C11: Exam Date (MMM-YYYY) | D11: Number of 1st Time Takers | E11: Number of 1st Time Passers | F11: Supporting Documentation
A12: Main Campus, Quezon City, Manila
A13: 1 | B13: Bachelor in Secondary Education Major in English | C13: 44562 | D13: 83 | E13: 72 | F13: 1. PRC Official Results
A14: 2 | B14: Bachelor in Secondary Education Major in Mathematics | C14: 44562 | D14: 165 | E14: 159
A15: 3 | B15: Bachelor in Secondary Education Major in Science | C15: 44562 | D15: 134 | E15: 130
A16: 4 | B16: Bachelor of Science in Accountancy | C16: 44835 | D16: 223 | E16: 198
A17: 5 | B17: Bachelor of Science in Civil Engineering | C17: 44682 | D17: 321 | E17: 321
A19: 1 | C19: 2 | D19: 3 | E19: 4 | F19: 5
A20: Undergraduate Program Offered | C20: Exam Date (MMM-YYYY) | D20: Number of 1st Time Takers | E20: Number of 1st Time Passers | F20: Supporting Documentation
A21: Main Campus ( BOAC CAMPUS-Tanza, Boac, Marinduque)
A22: 1 | B22: Bachelor of Science in Nursing | C22: May & November 2023 | D22: 90 | E22: 86
A23: 2 | B23: Bachelor of Science in Social Work | C23: September 2023 | D23: 52 | E23: 37
A24: 3 | B24: Bacelor of Science in Electrical Engineering | C24: April & September 2023 | D24: 26 | E24: 20
A25: 4 | B25: Bachelor of Science in Electronics Engineering | C25: April & October 2023 | D25: 18 | E25: 5
A26: 5 | B26: Bachelor of Science in Civil Engineering | C26: April & November 2023 | D26: 119 | E26: 57
A27: 6 | B27: Bachelor of Science in Mechanical Engineering | C27: February & August 2023 | D27: 16 | E27: 15
A28: 7 | B28: Bachelor of Secondary Education | C28: March & September 2023 | D28: 101 | E28: 86
A29: 8 | B29: Bachelor of Elementary Education | C29: March & September 2023 | D29: 23 | E29: 23
A30: Campus 2 (GASAN CAMPUS-Banuyo, Gasan, Marinduque)
A31: 1 | B31: Bachelor of Science in Fisheries | C31: October 2023 | D31: 7 | E31: 4
A32: Campus 4 (TORRIJOS CAMPUS-Poctoy, Torrijos, Marinduque)
A33: 1 | B33: Bachelor of Science in Agriculture | C33: November 2023 | D33: 16 | E33: 11
C35: Total | D35: =SUM(D22:D33) -> 468 | E35: =SUM(E22:E33) -> 344
C36: PERCENTAGE | D36: =E35/D35 -> 0.73504274
A38: Prepared by:
B41: JANINE JOIE M. ROCHA | C41: 45348
B42: AAII, Office of the President for Academic Affairs | C42: Date
A45: Approved:
B48: Prof. DIOSDADO P. ZULUETA, DPA | C48: 45348
B49: SUC President III | C49: Date

Sheet Higher Education (Oc2)
A1: NAME OF INSTITUTION: | B1: ((MARINDUQUE STATE COLLEGE))
A2: PROGRAM: | B2: HIGHER EDUCATION PROGRAM
A3: INDICATOR/S: | B3: Outcome Indicator 2: Percentage of graduates (2 years prior) that are employed
A4: INSTRUCTIONS: | B4: In Column 1, in the campus header, input the name and address of each campus. List down the degree program for each graduate. In Column 2 and Column 3, list down all the 1st semester FY 2021-2022 graduates per degree program and then provide the status for each graduate. In Column 4, input the employment, business, or company of the graduate. For this purpose, Employment refers to any mode or form of employment regardless of status, including self-employment.
A5: REFERENCES: | B5: ='Reference Matrix'!$E7 -> Summary Sheets
A6: MEANS OF VERIFICATION: | B6: ='Reference Matrix'!$F7 -> 1. Graduate tracer study 2. Result of survey of employed from the graduates in the 1st semester of FY 2021-2022, certified by the Registrar 3. Total Enrolment in the 1st Semester of AY 2021-2022, certified by the Registrar
A7: LINK TO GOOGLE DRIVE FOLDER: | B7: (https://drive.google.com/drive/folders/1Zezs1rJYwXox2umra5r2TT9W34aBuL09?usp=drive_link)
A9: SAMPLE
A10: 1 | C10: 2 | D10: 3 | G10: 4 | H10: 5
A11: Program Name | C11: Name of Graduate | D11: Graduate Tracer Status (Employed, Unemployed, Not Tracked) | G11: Name of Employment / Business / Company | H11: Supporting Documentation
A12: Main Campus, Quezon City, Manila | H12: 1. Graduate Tracer Study 2. Official list of FY 2021 Graduates
A13: Bachelor in Secondary Education Major in Mathematics | B13: 1 | C13: Surname, First Name, MI. | D13: Employed | G13: Self-employed
A14: Bachelor in Secondary Education Major in Science | B14: 2 | C14: Surname, First Name, MI. | D14: Unemployed
A15: Bachelor in Secondary Education Major in Science | B15: 3 | C15: Surname, First Name, MI. | D15: Not Tracked
A16: Bachelor of Science in Accountancy | B16: 4 | C16: Surname, First Name, MI. | D16: Employed | G16: ABC Corporation
A17: Bachelor of Science in Accountancy | B17: 5 | C17: Surname, First Name, MI. | D17: Employed | G17: DEF & Company
A18: TOTAL NUMBER OF STUDENTS Main Campus, Quezon City, Manila | C18: =COUNTIFS($A13:$A17,"*",$C13:$C17,"*",$D13:$D17,"*") -> 5 | D18: E | E18: UE | F18: NT
D19: =COUNTIFS($A13:$A17,"*",$C13:$C17,"*",$D13:$D17, "Employed") -> 3 | E19: =COUNTIFS($A13:$A17,"*",$C13:$C17,"*",$D13:$D17, "Unemployed") -> 1 | F19: =COUNTIFS($A13:$A17,"*",$C13:$C17,"*",$D13:$D17, "Not Tracked") -> 1
A21: 1 | C21: 2 | D21: 3 | G21: 4 | H21: 5
A22: Program Name | C22: Name of Graduate | D22: Graduate Tracer Status (Employed, Unemployed, Not Tracked) | G22: Name of Employment / Business / Company | H22: Supporting Documentation
A23: Main Campus ( BOAC CAMPUS-Tanza, Boac, Marinduque)
A24: Bachelor of Science in Civil Engineering | B24: 1 | C24: LAZARTE, Eduardson C. | D24: Employed | G24: Sunwest Inc.
A25: Bachelor of Science in Civil Engineering | B25: 2 | C25: LIAO, Cyrill James S. | D25: Not Tracked
A26: Bachelor of Science in Civil Engineering | B26: 3 | C26: MADLA, Arvin Laurence | D26: Employed | G26: Cogee International Devt. Inc, Parañaque
A27: Bachelor of Science in Civil Engineering | B27: 4 | C27: MALING, John Robert S. | D27: Employed | G27: Rwsi/ Roof and Wall Saver Inc. (Paranaque)
A28: Bachelor of Science in Civil Engineering | B28: 5 | C28: MARANDA, John Kalvin M. | D28: Not Tracked
A29: Bachelor of Science in Civil Engineering | B29: 6 | C29: OSINSAO, Mary Ann D. | D29: Not Tracked
A30: Bachelor of Science in Civil Engineering | B30: 7 | C30: SADIWA, Jeric P. | D30: Unemployed
A31: Bachelor of Science in Civil Engineering | B31: 8 | C31: SERDEÑA, Marielle L. | D31: Not Tracked
A32: Three Year Assocciate in Civil Engineering | B32: 1 | C32: SAGUID, Rex T. | D32: Unemployed
A33: Two Year Computer Technician | B33: 1 | C33: SAGUID, Errelyn F. | D33: Employed | G33: Iqor / Dasmariñas Cavite
A34: Bachelor of Science in Mechanical Engineering | B34: 1 | C34: MUHI, Justine Jay R. | D34: Not Tracked
A35: Bachelor of Science in Mechanical Engineering | B35: 2 | C35: SARINO, Charles Henry M. | D35: Not Tracked
A36: BSED - Biological Sciences | B36: 1 | C36: ALEMAN, Mark Allen B. | D36: Employed | G36: EnfraUSA , Ortigas
A37: BSED - Biological Sciences | B37: 2 | C37: SOLIS, John Emerson O. | D37: Not Tracked
A38: BSED - Mathematics | B38: 1 | C38: PIZARRA, Ervinjon L. | D38: Employed | G38: St. Mary's College of Marinduque/ Isok Boac Marinduque
A39: BSED - Mathematics | B39: 2 | C39: REVILLA, Mark Neil A. | D39: Not Tracked
A40: BSED - Music Education | B40: 1 | C40: LABOG, Ricabelle M. | D40: Employed | G40: Department of Social Welfare and Development
A41: BSED - Music Education | B41: 2 | C41: LABOG, Rina C. | D41: Employed | G41: Marinduque Provincial Hospital/Santol, Boac, Marinduque
A42: BSED - Music Education | B42: 3 | C42: LANCION, Anna Karenina SJ. | D42: Employed | G42: Mary Help of Christians College - Salesian Sisters Inc.
...

Sheet Higher Education (Op1)
B1: NAME OF INSTITUTION: | C1: (MARINDUQUE STATE COLLEGE)
B2: PROGRAM: | C2: HIGHER EDUCATION PROGRAM
B3: INDICATOR/S: | C3: Output Indicator 1: Percentage of undergraduate students enrolled in CHED-identified and RDC-identified priority programs
B4: INSTRUCTIONS: | C4: Kindly fill out Column 1 by listing all undergraduate programs offered in each campus. Please do not abbreviate or shorten program names. In Column 2, identify if the program offered is a priority program using the references listed below. Input the number of enrollees for each corresponding program. In Column 3, list down the documents submitted to verify the information provided in the previous columns. You may provide links to the electronic copies of supporting documents in this column.
B5: REFERENCES: | C5: ='Reference Matrix'!$E8 -> References in determining the disciplines/programs identified as priority offerings: a. CMO No. 5, s. 2019 b. CMO No. 10, s. 2021 c. CMO No. 7, s. 2023 d. RDC Resolutions
B6: MEANS OF VERIFICATION: | C6: ='Reference Matrix'!$F8 -> 1. Duly certified enrollment report for the 1st Semester of AY 2023-2024 per campus 2. Summary of Enrolment by identified priority undergraduate programs, and all other programs per campus 3. CHED-identified priority programs listed in CHED Memorandum Order (CMO) No. 5, s. 2019 and CMO No. 10, s. 2021 4. For programs considered priority outside those identified by CHED, submit certification, resolution from RDC or similar Government Councils, etc.
B7: LINK TO GOOGLE DRIVE FOLDER: | C7: (https://drive.google.com/drive/folders/1Zezs1rJYwXox2umra5r2TT9W34aBuL09?usp=drive_link)
A9: SAMPLE
A10: 1 | C10: 2 | E10: 3
A11: Undergraduate Program Offered | C11: No. of Enrollees for 1st Semester AY 2023-2024 | E11: Supporting Documentation
C12: Priority Program | D12: Non-Priority Program
A13: Main Campus, Quezon City, Manila | E13: 1. Certified Enrollment Report for 1st Semester AY 2023-2024 2. CHED Memorandum Order No. 10, s. 2021
A14: 1 | B14: Bachelor in Secondary Education Major in English | D14: 85
A15: 2 | B15: Bachelor in Secondary Education Major in Mathematics | C15: 165
A16: 3 | B16: Bachelor in Secondary Education Major in Science | C16: 134
A17: 4 | B17: Bachelor of Arts in Social Sciences | C17: 199
A18: 5 | B18: Bachelor of Science in Accountancy | C18: 223
A19: 6 | B19: Bachelor of Science in Civil Engineering | C19: 321
A21: 1 | C21: 2 | E21: 3
A22: Undergraduate Program Offered | C22: No. of Enrollees for 1st Semester AY 2023-2024 | E22: Supporting Documentation
C23: Priority Program | D23: Non-Priority Program
A24: Boac Main Campus-Tanza, Boac, Marinduque
A25: 1 | B25: Bachelor of Science in Civil Engineering | C25: 431
A26: 2 | B26: Bachelor of Science in Computer Engineering | C26: 144
A27: 3 | B27: Bachelor of Science in Electrical Engineering | C27: 161
A28: 4 | B28: Bachelor of Science in Electronics Engineering | C28: 94
A29: 5 | B29: Bachelor of Science in Mechanical Engineering | C29: 161
A30: 6 | B30: Bachelor of Science in Industrial Technology | C30: 1673
A31: 7 | B31: Bachelor of Science in Information Technology | C31: 729
A32: 8 | B32: Bachelor of Science in Information System | C32: 248
A33: 9 | B33: Bachelor of Secondary Education | C33: 306
A34: 10 | B34: Bachelor of Culture and Arts Education | C34: 103
A35: 11 | B35: Bachelor of Technology and Livelihood Education | C35: 103
A36: 12 | B36: Bachelor of Arts in English Language Studies | D36: 162
A37: 13 | B37: Bachelor of Arts in Communication | C37: 233
A38: 14 | B38: Bachelor of Science in Social Works | C38: 280
A39: 15 | B39: Bachelor of Science in Entrepreneurship-Entrepreneurial Management | C39: 248
A40: 16 | B40: Bachelor of Science in Business Administration | C40: 855
A41: 17 | B41: Bachelor of Science in Accountancy | C41: 103
A42: 18 | B42: Bachelor of Science in Law Enforcement Administration | D42: 290
...

Sheet Higher Education (Op2)
B1: NAME OF INSTITUTION: | C1: (MARINDUQUE STATE COLLEGE)
B2: PROGRAM: | C2: HIGHER EDUCATION PROGRAM
B3: INDICATOR/S: | C3: Output Indicator 2: Percentage of undergraduate programs with accreditation
B4: INSTRUCTIONS: | C4: In Column 1, list down all undergraduate degree programs offered by the institution. Input the Year of Initial Operation of each degree program in Column 2. In Column 3, select the Program Accreditation Status of each program from the dropdown menu. In Column 4, provide the Validity of Accreditation of each program. Refer to the issued accreditation certificate. Provide descriptions and links to supporting documentation in Column 5.
B5: REFERENCES: | C5: ='Reference Matrix'!$E9 -> Accreditation includes those issued by local and international bodies recognized by CHED; CMO No. 1, s. 2005; AACCUP (Level 1 - Level 4)
B6: MEANS OF VERIFICATION: | C6: ='Reference Matrix'!$F9 -> 1. Accreditation Certificates 2. List of all undergraduate programs per campus with accreditation (include date of validity) or without accreditation (include reasons for non-accreditation), and indicate year of initial operation of each of the programs being offered
B7: LINK TO GOOGLE DRIVE FOLDER: | C7: (https://drive.google.com/drive/folders/1Zezs1rJYwXox2umra5r2TT9W34aBuL09?usp=drive_link)
A9: SAMPLE
A10: 1 | C10: 2 | D10: 3 | E10: 4 | G10: 5
A11: Undergraduate Programs Offered | C11: Year of Initial Operation | D11: Program Accreditation Status | E11: Validity of Accreditation (Ref. Accreditation Certificate) | G11: Supporting Documentation / Reason for Non-Accreditation
E12: Start Date (MMM-DD-YYYY) | F12: End Date (MMM-DD-YYYY)
A13: Main Campus, Quezon City, Manila
A14: 1 | B14: Bachelor in Secondary Education Major in English | C14: 2012 | D14: Candidate | G14: Preliminary Survey conducted last November 20-23, 2023. Scanned copy of the report can be accessed here: tinyurl.com/SampleLink
A15: 2 | B15: Bachelor in Secondary Education Major in Mathematics | C15: 2003 | D15: Level 1 | E15: 43312 | F15: 44043 | G15: Accreditation certificate lapsed due to deficiency of requirements; scheduled for accreditation visit on February 12, 2024. Communication with AACCUP regarding the schedule is attached. Scanned copy of this file can be accessed here: tinyurl.com/SampleLink
A16: 3 | B16: Bachelor in Secondary Education Major in Science | C16: 2000 | D16: Level 2 | E16: 44926 | F16: 45657 | G16: AACCUP Accreditation Certificate
A17: 4 | B17: Bachelor of Arts in Social Sciences | C17: 1999 | D17: Level 3 | E17: 44926 | F17: 45657 | G17: AACCUP Accreditation Certificate
A18: 5 | B18: Bachelor of Science in Accountancy | C18: 1984 | D18: Level 4 | E18: 44927 | F18: 46752 | G18: AACCUP Accreditation Certificate
A19: 6 | B19: Bachelor of Science in Civil Engineering | C19: 2022 | D19: Not Accreditable | G19: Program is being offered for less than five (5) years and has not yet reached the required batch of graduates.
A21: 1 | C21: 2 | D21: 3 | E21: 4 | G21: 5
A22: Undergraduate Programs Offered | C22: Year of Initial Operation | D22: Program Accreditation Status | E22: Validity of Accreditation (Ref. Accreditation Certificate) | G22: Supporting Documentation
E23: Start Date (MMM-DD-YYYY) | F23: End Date (MMM-DD-YYYY)
A24: MSC Boac Main Campus (Tanza, Boac, Marinduque)
A25: 1 | B25: Bachelor of Secondary Education | C25: 1986-1987 | D25: Level III Re- Accredited | E25: October 1, 2022 | F25: 45170 | G25: BSED.pdf
A26: 2 | B26: BS in Civil Engineering | C26: 1998-1999 | D26: Level III Re- Accredited | E26: May 16, 2021 | F26: May 15, 2025 | G26: https://drive.google.com/file/d/1RBZJ4kbt7M8Uw36U8kBNqZioFKRZFaTW/view?usp=drive_link
A27: 3 | B27: BS in Electrical Engineering | C27: 1998-1999 | D27: Level III Re- Accredited | E27: May 16, 2021 | F27: May 15, 2025 | G27: https://drive.google.com/file/d/1I7pFuxdlxG3_9VejHJooifR9q174QeKB/view?usp=drive_link
A28: 4 | B28: BS in Computer Engineering | C28: 2008-2009 | D28: Level III Re- Accredited | E28: July 1, 2021 | F28: June 30, 2025 | G28: https://drive.google.com/file/d/1E2AoSD-jmdxJHuHAh1SOU7QVAde-1U5x/view?usp=drive_link
A29: 5 | B29: BS in Electronics Engineering | C29: 2008-2009 | D29: Level III Re- Accredited | E29: July 1, 2021 | F29: June 30, 2025 | G29: https://drive.google.com/file/d/1gPyRbIskD43gzfdEnNAKOTNsW56-9wRu/view?usp=sharing
A30: 6 | B30: BS in Information Systems | C30: 1998-1999 | D30: Level III Re- Accredited | E30: January 1, 2020 | F30: December 31, 2023 | G30: https://drive.google.com/file/d/1TjtAhJbaW98X-MEjpgqDIjyhjE-78xtQ/view?usp=drive_link
A31: 7 | B31: BS in Information Technology | C31: 1998-1999 | D31: Level III Re- Accredited | E31: January 1, 2020 | F31: December 31, 2023 | G31: https://drive.google.com/file/d/1BLZlFIoQdzvY57nA3F49Od6rovaLsN06/view?usp=drive_link
A32: 8 | B32: BS in Industrial Technology maj in Automotive, Mechanical, Food, Electrical, Drafting, Refrigiration & Air conditioning & Welding and fabrication | C32: 1989-1990 | D32: Level III Re- Accredited | E32: January 1, 2020 | F32: December 31, 2023 | G32: https://drive.google.com/file/d/1AzxNReDjg1wh4i_8amlC-nwN_iC8_mZT/view?usp=sharing
A33: 9 | B33: BA in Communication | C33: 2010-2011 | D33: Level III Re- Accredited | E33: October 16, 2021 | F33: October 15, 2025 | G33: https://drive.google.com/file/d/1KPFKZLaR3rj5BdHV0gPxyYZWTyWS9i3k/view?usp=sharing
A34: 10 | B34: BA in English Language Studies | C34: 2006-2007 | D34: Level III Re- Accredited | E34: October 16, 2021 | F34: October 15, 2025 | G34: https://drive.google.com/file/d/1gBf2ddZ5SrF2zCfKzNz2tFrkgLSzSWO_/view?usp=sharing
A35: 11 | B35: BS in Entrepreneurship | C35: 2006-2007 | D35: Level III Re- Accredited | E35: July 1, 2021 | F35: June 30, 2025 | G35: https://drive.google.com/file/d/1ftqttYhNaFBFXdPCPrzIQTBZ3nynLzJC/view?usp=sharing
A36: 12 | B36: BS in Nursing | C36: 2006-2007 | D36: Level III Re- Accredited | E36: July 1, 2021 | F36: June 30, 2025 | G36: https://drive.google.com/file/d/1vYaVHLoxzRtf-6Zs3A4Qp1_02C-R7BEM/view?usp=sharing
A37: 13 | B37: Bachelor of Public Administration | C37: 2012-2013 | D37: Level II Re- Accredited | E37: July 1, 2022 | F37: June 30, 2026 | G37: https://drive.google.com/file/d/12luzk4O4EYlQGQppOay4M1JzdRBRpOjS/view?usp=sharing
... A46: 22 | B46: BS in Business Administration | C46: 2018-2019 | D46: Accreditable | E46: N/A | F46: N/A | G46: (For Preliminary Survey Visit)
A47: MSC Sta.Cruz Campus
A48: 1 | B48: Bachelor of Elementary Education major in Pre-Elementary & General Education | C48: 1992-1993 | D48: Level 3 | E48: December 16, 2020 | F48: December 15, 2024 | G48: https://drive.google.com/file/d/12nYQlPZZKFKkDkiXavMzmHAaXRjvTSz5/view?usp=sharing
A49: 2 | B49: AB in Political Science | C49: 1992-1993 | D49: Level 2 | E49: October 1, 2022 | F49: 45170
A50: 3 | B50: BS in Information Systems (SC) | C50: 1998-1999 | D50: Level 2 | E50: 44378 | F50: 46174
...

Sheet Advanced Education (Oc1)
B1: NAME OF INSTITUTION: | C1: (MARINDUQUE STATE COLLEGE)
B2: PROGRAM: | C2: ADVANCED EDUCATION PROGRAM
B3: INDICATOR/S: | C3: Outcome Indicator 1: Percentage of graduate school faculty engaged in research work applied in any of the following: a) pursuing advanced research degree programs (doctorate degree) or b) actively pursuing within the last three (3) years (investigative research, basic and applied scientific research, policy research, social science research) or c) producing technologies for commercialization or livelihood improvement or d) whose research work resulted in an extension program
B4: INSTRUCTIONS: | C4: Kindly fill out Column 1 by listing all graduate school faculty members. In Column 2, list the position or designation of the respective faculty members. In Column 3, select the category of engagement of each listed faculty member. In Column 4, list down the documents submitted to verify the information provided in the previous columns. You may provide links to the electronic copies of supporting documents in this column.
B5: REFERENCES: | C5: ='[1]Reference Matrix'!$E11 -> 0
B6: MEANS OF VERIFICATION: | C6: ='[1]Reference Matrix'!$F11 -> 0
B7: LINK TO GOOGLE DRIVE FOLDER: | C7: (https://drive.google.com/drive/folders/1Zezs1rJYwXox2umra5r2TT9W34aBuL09?usp=drive_link)
A9: SAMPLE
A10: 1 | C10: 2 | D10: 3 | E10: 4
A11: Name of Faculty | C11: Position | D11: Category | E11: Supporting Documentation / Means of Verification
A12: 1 | B12: Surname, First Name, MI. | C12: Instructor I | D12: A: Pursuinng advance degree programs | E12: Scanned copy of enrollment form
A13: 2 | B13: Cruz, Juana E. | C13: Associate Professor II | D13: B: Actively pursing research within the last three (3) years | E13: Scanned copy of latest research conducted
A14: 3 | B14: Dela Cruz, Juan M. | C14: Associate Professor III | D14: C: Producing technologies for commercialization or livelihood improvement | E14: Documentation of utilized technlogy
A15: 4 | B15: Flores, John D. | C15: University Professor V | D15: D: Whose research work resulted in an extension program | E15: Activity report of extension program
A16: 5 | B16: Reyes, Jose G. | C16: Board Secretary | D16: E: Not applicable
A17: 6 | B17: Santos, Joanna L. | C17: Associate Professor I | D17: A: Pursuinng advance degree programs | E17: Scanned copy of enrollment form
A19: 1 | C19: 2 | D19: 3 | E19: 4
A20: Name of Faculty | C20: Position | D20: Faculty Engagement | E20: Supporting Documentation / Means of Verification
A21: {=IFERROR(SEQUENCE(COUNTA(B21:B40)),1)} -> 1 | B21: Atienza, Cristina S. | C21: I1 | D21: E: Not applicable
A22: 2 | B22: Benedicto, Wilbert P. | C22: I1 | D22: E: Not applicable
A23: 3 | B23: Blase, Ma. Edelwina M. | C23: P4 | D23: B: Actively pursing research within the last three (3) years | E23: Documentation
A24: 4 | B24: Capina, Verna Liza L. | C24: ASO5 | D24: E: Not applicable
A25: 5 | B25: Cuevas, Abraham L. | C25: ASO2 | D25: E: Not applicable
A26: 6 | B26: Go, Vili Dane M. | C26: I1 | D26: E: Not applicable
A27: 7 | B27: Jalos, Leodegario Jr. M. | C27: ASO5 | D27: E: Not applicable
A28: 8 | B28: Labatete, Anne Grace M. | C28: ASO2 | D28: B: Actively pursing research within the last three (3) years | E28: Documentation
A29: 9 | B29: Malvar, Romulo H. | C29: CP | D29: E: Not applicable
A30: 10 | B30: Manoos, Liza Marie M. | C30: ASO5 | D30: E: Not applicable
A31: 11 | B31: Montejo, Joy S. | C31: ASOI | D31: E: Not applicable
A32: 12 | B32: Nabos, Christine May L. | C32: I1 | D32: B: Actively pursing research within the last three (3) years | E32: Documentation
A33: 13 | B33: Nabos, Julieta Q. | C33: ASO2 | D33: C: Producing technologies for commercialization or livelihood improvement | E33: Documentation
A34: 14 | B34: Palomares, Noel R. | C34: ASI3 | D34: D: Whose research work resulted in an extension program | E34: Documentation
A35: 15 | B35: Pineda, Susan B. | C35: ASO5 | D35: B: Actively pursing research within the last three (3) years | E35: Documentation
A36: 16 | B36: Regalia, Marites R. | C36: I1 | D36: E: Not applicable
A37: 17 | B37: Ricafrente, Jellian T. | C37: ASO2 | D37: E: Not applicable
A38: 18 | B38: Zulueta, Diosdado P. | C38: CP | D38: E: Not applicable
D41: PERCENTAGE
B42: A: | C42: =COUNTIF($D$21:$D$40, "*"&B42&"*") -> 0 | D42: =$C42/$C$47 -> 0
B43: B: | C43: =COUNTIF($D$21:$D$40, "*"&B43&"*") -> 4 | D43: =$C43/$C$47 -> 0.22222222
B44: C: | C44: =COUNTIF($D$21:$D$40, "*"&B44&"*") -> 1 | D44: =$C44/$C$47 -> 0.055555556
...

Sheet Advanced Education (Op1_SC)
B1: NAME OF INSTITUTION: | C1: (MARINDUQUE STATE COLLEGE)
B2: PROGRAM: | C2: ADVANCED EDUCATION PROGRAM
B3: INDICATOR/S: | C3: Output Indicator 1 For State Colleges and Professional Institutes: Percentage of graduate students enrolled in CHED-identified or RDC-identified priority programs
B4: INSTRUCTIONS: | C4: Kindly fill out Column 1 by listing all graduate programs offered in each campus. Please do not abbreviate or shorten program names. In Column 2, identify if the program offered is a priority program using the references listed below. In Column 3, input the number of enrollees for each corresponding program. In Column 4, list down the documents submitted to verify the information provided in the previous columns. You may provide links to the electronic copies of supporting documents in this column.
B5: REFERENCES: | C5: {="For State Colleges and Professional Institutes:"&CHAR(10)&'Reference Matrix'!$E13} -> For State Colleges and Professional Institutes: References in determining the disciplines/programs identified as priority offerings: a. CMO No. 5, s. 2019 b. CMO No. 10, s. 2021 c. CMO No. 7, s. 2023 d. RDC Resolutions
B6: MEANS OF VERIFICATION: | C6: {="For State Colleges and Professional Institutes:"&CHAR(10)&'Reference Matrix'!$F13} -> For State Colleges and Professional Institutes: 1. Duly certified enrollment report 2. Summary of Enrolment by identified priority graduate programs, and all other programs per campus 3. For programs considered priority outside those identified by the CHED, submit certification, resolution from RDC or similar Government Councils, etc.
B7: LINK TO GOOGLE DRIVE FOLDER: | C7: (https://drive.google.com/drive/folders/1Zezs1rJYwXox2umra5r2TT9W34aBuL09?usp=drive_link)
A9: SAMPLE
A10: 1 | C10: 2 | E10: 3
A11: Undergraduate Program Offered | C11: No. of Enrollees for 1st Semester AY 2023-2024 | E11: Supporting Documentation
C12: Priority Program | D12: Non-Priority Program
A13: Main Campus, Quezon City, Manila | E13: 1. Certified Report for Graduate Students Enrolled in 1st Semester AY 2023-2024 2. CHED Memorandum Order No. 10, s. 2021 3. RDC Resolutions
A14: 1 | B14: Doctor of Philosophy in Agriculture | C14: 88
A15: 2 | B15: Doctor of Philosophy in Education | C15: 78
A16: 3 | B16: Doctor of Public Administration | D16: 112
A17: 4 | B17: Master in Information Technology | C17: 10
A18: 5 | B18: Master in Public Administration | D18: 89
A19: 6 | B19: Master in Business Administration | C19: 90
A21: 1 | C21: 2 | E21: 3
A22: Undergraduate Program Offered | C22: No. of Enrollees for 1st Semester AY 2023-2024 | E22: Supporting Documentation
C23: Priority Program | D23: Non-Priority Program
A24: Main Campus (Please identify the name of campus and location)
A25: 1 | B25: Doctor of Education | C25: 43
A26: 2 | B26: Master Arts in Education | C26: 457
A27: 3 | B27: Master of Public Administration | C27: 45 | D27: 30
A28: 4 | B28: Master in Information Technology | C28: 7
A29: 5
B31: Sub Total | C31: =SUM(C25:C30) -> 552 | D31: =SUM(D25:D30) -> 30
B32: Total Number of Enrollees | C32: =SUM(C31:D31) -> 582
B33: PERCENTAGE | C33: =C31/C32 -> 0.94845361
A35: Prepared by:
B38: GEMMA A. TIROL | C38: 45348
B39: College Registrar | C39: Date
A42: Approved:
B45: Prof. DIOSDADO P. ZULUETA, DPA | C45: 45348
B46: SUC President III | C46: Date

Sheet Advanced Education (Op2)
B1: NAME OF INSTITUTION: | C1: (MARINDUQUE STATE COLLEGE)
B2: PROGRAM: | C2: ADVANCED EDUCATION PROGRAM
B3: INDICATOR/S: | C3: Output Indicator 2: Percentage of accredited graduate programs
B4: INSTRUCTIONS: | C4: In Column 1, list down all graduate degree programs offered by the institution. Input the Year of Initial Operation of each degree program in Column 2. In Column 3, select the Program Accreditation Status of each program from the dropdown menu. In Column 4, provide the Validity of Accreditation of each program. Refer to the issued accreditation certificate. Provide descriptions and links to supporting documentation in Column 5.
B5: REFERENCES: | C5: ='Reference Matrix'!$E14 -> Accreditation includes those issued by local and international bodies recognized by CHED; AACCUP (Level 1 - Level 4)
B6: MEANS OF VERIFICATION: | C6: ='Reference Matrix'!$F14 -> 1. Accreditation Certificates 2. List of all graduate programs per campus with or without accreditation (include reasons for non-accreditation), indicate year of initial operation
B7: LINK TO GOOGLE DRIVE FOLDER: | C7: (https://drive.google.com/drive/folders/1Zezs1rJYwXox2umra5r2TT9W34aBuL09?usp=drive_link)
A9: SAMPLE
A10: 1 | C10: 2 | D10: 3 | E10: 4 | G10: 5
A11: Undergraduate Programs Offered | C11: Year of Initial Operation | D11: Program Accreditation Status | E11: Validity of Accreditation (Ref. Accreditation Certificate) | G11: Supporting Documentation / Reason for Non-Accreditation
E12: Start Date (MMM-DD-YYYY) | F12: End Date (MMM-DD-YYYY)
A13: Main Campus, Quezon City, Manila
A14: 1 | B14: Master in Information Technology | C14: 2012 | D14: Candidate | G14: Preliminary Survey conducted last November 20-23, 2023. Scanned copy of the report can be accessed here: tinyurl.com/SampleLink
A15: 2 | B15: Master in Public Administration | C15: 2003 | D15: Level 1 | E15: 43312 | F15: 44043 | G15: Accreditation certificate lapsed due to deficiency of requirements; scheduled for accreditation visit on February 12, 2024. Communication with AACCUP regarding the schedule is attached. Scanned copy of this file can be accessed here: tinyurl.com/SampleLink
A16: 3 | B16: Master in Business Administration | C16: 2000 | D16: Level 2 | E16: 44926 | F16: 45657 | G16: AACCUP Accreditation Certificate
A17: 4 | B17: Doctor of Philosophy in Agriculture | C17: 1999 | D17: Level 3 | E17: 44926 | F17: 45657 | G17: AACCUP Accreditation Certificate
A18: 5 | B18: Doctor of Philosophy in Education | C18: 1984 | D18: Level 4 | E18: 44927 | F18: 46752 | G18: AACCUP Accreditation Certificate
A19: 6 | B19: Doctor of Public Administration | C19: 2022 | D19: Not Accreditable | G19: Program is being offered for less than five (5) years and has not yet reached the required batch of graduates.
A21: 1 | C21: 2 | D21: 3 | E21: 4 | G21: 5
A22: Undergraduate Programs Offered | C22: Year of Initial Operation | D22: Program Accreditation Status | E22: Validity of Accreditation (Ref. Accreditation Certificate) | G22: Supporting Documentation
E23: Start Date (MMM-DD-YYYY) | F23: End Date (MMM-DD-YYYY)
A24: MSC Boac Main Campus (Tanza, Boac, Marinduque)
A25: 1 | B25: Master of Arts in Education major in Educational Management | C25: 1987-1988 | D25: Level 3 | E25: October 1, 2023 | F25: 46660 | G25: https://drive.google.com/file/d/1xsdZO-ctsqogSlVqtNkjDeEDdg3U1uYI/view?usp=sharing
A26: 2 | B26: Master in Public Administration major in: Organizational Studies/ Local Government and Regional Administration | C26: 1995-1996 | D26: Level 3 | E26: October 1, 2023 | F26: 46660 | G26: https://drive.google.com/file/d/1xsdZO-ctsqogSlVqtNkjDeEDdg3U1uYI/view?usp=sharing
A27: 3 | B27: Doctor of Education major in Curriculum Development and Management | C27: 2008-2009 | D27: Level 2 | E27: October 1, 2022 | F27: 45170 | G27: https://drive.google.com/file/d/1-OJ0wAAgggVvXPwl9uBq4C0cgqvEVOXJ/view?usp=sharing
B29: Number of Programs Offered: | D29: =COUNTIFS($B25:B28,"<>",D25:D28,"<>") -> 3
B30: Number of Accredited Programs: | D30: 3
B31: Number of Accreditable Programs: | D31: =D29-COUNTIF(D25:D28,"Not Accreditable") -> 3
B32: PERCENTAGE | D32: =D30/D31 -> 1
A35: Prepared by:
B38: MENANDRO M. MERLIN, DEM | C38: 45348
B39: IQA Director | C39: Date
A42: Approved:
B45: Prof. DIOSDADO P. ZULUETA, DPA | C45: 45348
B46: SUC President III | C46: Date

Sheet Research Program (Op&Oc)
B1: NAME OF INSTITUTION: | C1: (MARINDUQUE STATE COLLEGE)
B2: PROGRAM: | C2: RESEARCH PROGRAM
B3: INDICATOR/S: | C3: Outcome Indicator 1: Number of research outputs in the last three years (FY 2021-2023) utilized by the industry or by other beneficiaries Output Indicator 1: Number of research outputs completed within the year Output Indicator 2 (For State Universities): Percentage of researches published within the year (FY 2023) in internationally-refereed journal Output Indicator 2 (For State Colleges and Professional Institutes): Percentage of researches presented within the year (FY 2023) in national, regional, and international fora
B4: INSTRUCTIONS: | C4: In the columns under Details of Research Outputs, list all faculty research outputs completed within the past three years. Please include the year of completion for each research output listed. For each research output, fill in the corresponding information on its presentation, publication, and/or utilization. Kindly fill all fields. Please indicate N/A if the field is not applicable for the research output. For State Colleges, please fill in the requested information under the Details of Presentation columns of corresponding research outputs completed in FY 2021, 2022, and 2023. Please note that in-house presentations/reviews will not be considered. For State Universities, please fill in the requested information under Details of Publication columns of corresponding research outputs completed in FY 2021, 2022, and 2023. Please be reminded that incomplete entries in this form will be disregarded.
B5: REFERENCES: | C5: {="For Outcome Indicator 1:"&CHAR(10)&'Reference Matrix'!$E16&CHAR(10)&CHAR(10)&"For Output Indicator 1:"&CHAR(10)&'Reference Matrix'!$E17&CHAR(10)&CHAR(10)&"For Outcome Indicator 2 (State Universities):"&CHAR(10)&'Reference Matrix'!$E18&CHAR(10)&CHAR(10)&"For Outcome Indicator 2 (State Colleges and Professional Institutes):"&CHAR(10)&'Reference Matrix'!$E19} -> For Outcome Indicator 1: Utilized by industry or other beneficiaries refers to the adopters/partners/communities, external to the institution For Output Indicator 1: Research outputs may comprise any or all of the following: 1. Completed research-based papers; 2. Research-based papers or articles published in journals or international refereed publications that are not in the Beall's List of Predatory Journals; 3. Research-based papers or articles presented in international, national, or regional fora or conferences; 4. Inventions or innovations, methods, composition, or processes as a result of research 5. Models/inventions duly patented and applied for commercial purposes or utilized/adopted for development/production/service provision For Outcome Indicator 2 (State Universities): Beall's List of Predatory Journals Documentation on the details of journals to qualify in internationally refereed journals For Outcome Indicator 2 (State Colleges and Professional Institutes): In-house review presentations are not included nor considered as presentations in qualified fora.
B6: MEANS OF VERIFICATION: | C6: ="For Outcome Indicator 1:"&CHAR(10)&'Reference Matrix'!$F16&CHAR(10)&CHAR(10)&"For Output Indicator 1:"&CHAR(10)&'Reference Matrix'!$F17&CHAR(10)&CHAR(10)&"For Outcome Indicator 2 (State Universities):"&CHAR(10)&'Reference Matrix'!$F18&CHAR(10)&CHAR(10)&"For Outcome Indicator 2 (State Colleges and Professional Institutes):"&CHAR(10)&'Reference Matrix'!$F19 -> For Outcome Indicator 1: 1. Proof that the research output was utilized by identified stakeholders/beneficiaries 2. MOAs/MOUs 3. Reports with testimonies 4. Certification from industries/beneficiaries on the utilization of research outputs For Output Indicator 1: 1. Abstracts of research outputs 2. Certificate of completion signed by the Research Director/Vice President for Research For Outcome Indicator 2 (State Universities): 1. Photocopy of the journal's title page, and 1st page of the article published For Outcome Indicator 2 (State Colleges and Professional Institutes): 1. Conference proceeding indicating research article presented 2. Program of activities and attendance to the conference 3. Certificate of participation / recognition for presenting the research output
B7: LINK TO GOOGLE DRIVE FOLDER: | C7: (https://drive.google.com/drive/folders/1Zezs1rJYwXox2umra5r2TT9W34aBuL09?usp=drive_link)
A9: SAMPLE
A10: Details of Research Outputs | G10: Details of Presentation | K10: Details of Publication | Q10: Details of Utilized Output
A11: Research Title | C11: Name of Faculty Researcher / Author | D11: Status of Research | E11: Duration of Research | G11: Title of Forum | H11: Venue | I11: Forum Type | J11: Date of Presentation (MMM-DD-YYYY) | K11: Published Title | L11: Date of Publication (MMM-DD-YYYY) | M11: Title of Journal / Publication | N11: Volume & Issue | O11: ISSN / ISBN | P11: Index | Q11: Product Name / Methods / Process / Technology | R11: Patent Number / Product Description | S11: Benefiting Industry / Community
E12: Date Started (MMM-DD-YYYY) | F12: Date of Completion (MMM-DD-YYYY)
A13: 1 | B13: Sample Research Title 1 | C13: Flores, John D. | D13: Completed | E13: 43479 | F13: 45138 | G13: N/A | H13: N/A | I13: N/A | J13: N/A | K13: Sample Research Title 1 | L13: 45212 | M13: Journal of Environmental Science and Management | N13: Volume 26 No 1 (2023) | O13: SSN 0119-1144 | P13: Science Citation Index Expanded | Q13: Product of Sample Research 1 | R13: This product represents the culmination of rigorous research, offering a comprehensive and cutting-edge approach to develop new products from recyclable materials which can be commercialized for profit of small and medium enterprises. | S13: Small and medium-sized enterprises (SMEs)
A14: 2 | B14: Sample Research Title 2 | C14: Santos, Joanna L. | D14: Completed | E14: 44480 | F14: 44855 | G14: Knowledge Nexus: Exploring Frontiers in Research | H14: Philippine International Convention Center, PICC Complex, Pasay, Manila | I14: National | J14: 44887 | K14: Sample Research Title 2 | L14: 44908 | M14: Journal of Environmental Science and Management | N14: Volume 26 No 1 (2023) | O14: SSN 0119-1144 | P14: Science Citation Index Expanded | Q14: N/A | R14: N/A | S14: N/A
A15: 3 | B15: Sample Research Title 3 | C15: Dela Cruz, Juan M. | D15: Completed | E15: 43843 | F15: 44571 | G15: Regional Insight Summit: Unveiling Perspectives through Local Research Excellence | H15: SMX Convention Center, Clark, Pampanga | I15: Regional | J15: 45037 | K15: N/A | L15: N/A | M15: N/A | N15: N/A | O15: N/A | P15: N/A | Q15: N/A | R15: N/A | S15: N/A
A16: 4 | B16: Sample Research Title 4 | C16: Cruz, Juana E. | D16: Completed | E16: 43549 | F16: 44200 | G16: Global Symposium on Advanced Research and Innovation 2023 | H16: Renaissance Convention Center, Singapore | I16: International | J16: 44279 | K16: N/A | L16: N/A | M16: N/A | N16: N/A | O16: N/A | P16: N/A | Q16: N/A | R16: N/A | S16: N/A
A17: 5 | B17: Sample Research Title 5 | C17: Cruz, Juana E. | D17: On-going | E17: 45243
A19: Details of Research Outputs | G19: Details of Presentation | K19: Details of Publication | Q19: Details of Utilized Output
A20: Research Title | C20: Name of Faculty Researcher / Author | D20: Status of Research | E20: Duration of Research | G20: Title of Forum | H20: Venue | I20: Forum Type | J20: Date of Presentation | K20: Published Title | L20: Date of Publication | M20: Title of Journal / Publication | N20: Volume & Issue | O20: ISSN / ISBN | P20: Index | Q20: Product Name / Methods / Process / Technology | R20: Patent Number / Product Description | S20: Benefiting Industry / Community
E21: Date Started (MMM-DD-YYYY) | F21: Date of Completion (MMM-DD-YYYY)
B22: 2023
A23: 1 | B23: Level of Satisfaction of the Residents of Brgy. Pili, Mogpog, Marinduque on Government Service Delivery | C23: Generoso E. Udanga Abraham L. Cuevas | D23: Completed | E23: 44850 | F23: 44941 | G23: PSU BIMP-EAGA International Research Conference | H23: City State Asturias Hotel, Puerto Princesa, Palawan | I23: International | J23: 44966 | Q23: E-salba for Disaster and Health Risk Reduction | R23: This activity is a result of the research collaboration with Mapua University about the development of health index: vulnerability to extreme environmental events for Marinduque Island with the e-Salba user application to be used for health and disaster risk reduction in the province of Marinduque. | S23: Local Government Units of Marinduque
A24: 2 | B24: Lived Experiences of Selected MSMEs on Technological Assistance | C24: Michael V. Capiña | D24: Completed | E24: 44829 | F24: 44951 | G24: 2023 International Conference on Sustainable Agri-vironment Education, Entrepreneurship, and Community Development (ICSAVED) | H24: Mariano Marcos State Univeristy | I24: International | J24: March 14-17, 2023
A25: 3 | B25: Tracer Study of Diploma in Midwifery Graduates in the Marinduque State College from 2006-2022 | C25: Abegail O. Magcamit | D25: Completed | E25: 44835 | F25: 44986 | G25: 35th APSOM Annual Convention – Association of Philippine Schools of Midwifery, Inc | H25: Century Park Hotel, Malate, Manila | I25: National | J25: April 19-20, 2023
A26: 4 | B26: Level of Satisfaction in Maternal and Child Health Care Services of the BEmONC Facility as perceived by parents in Ten Barangays of Buenavista, Marinduque, Philippines | C26: Divina R. Vitto | D26: Completed | E26: 44621 | F26: 44987 | G26: 35th APSOM Annual Convention – Association of Philippine Schools of Midwifery, Inc | H26: Century Park Hotel, Malate, Manila | I26: National | J26: April 19-20, 2023
A27: 5 | B27: Training Needs Assessment of Barangay Officials in the Municipalities of Torrijos and Buenavista, Marinduque | C27: Joy R. Profugo Wilmer L. Imperio Neil Ryan P. Rodil | D27: Completed | E27: 44866 | F27: 45017 | G27: 6th International Conference in Research, Education, Management, and the Social Sciences | H27: Crown Legacy Hotel, Baguio City | I27: International | J27: April 15-17, 2023 | Q27: Rapid Assessment of Cave | R27: This is a product of the research on : Cave Bio-physical Characterization: GIS - Based Mapping in partnership with DENR-PENRO for the assessment and mapping of uncharted caves in the province of Marinduque | S27: DENR-PENRO
A28: 6 | B28: Evaluating Resident Satisfaction with Tourism Promotion Program in Barangay Pili, Mogpog, Marinduque: Implications to Local Tourism Management | C28: Generoso E. Udanga | D28: Completed | E28: 44850 | F28: 44941 | G28: International Hospitality and Tourism Research AMPAYAG: 1st International Conference Conference | H28: Laoag City, Ilocos Norte | I28: International | J28: May 18-19, 2023 | Q28: Effective management of Marinduque Wildlife Sanctuary | R28: This initiative is part of the ongoing partnership with DENR-PENRO on the Biophysical, Socio-Economic and Vulnerability Assessments of the Marinduque Wildlife Sanctuary (MWS): A Basis for the Formulation of the Protected Area Management Plan for a resilient and effective management of MWS in Tumagabok, Marinduque | S28: LGU Boac PAMB, PAMO, TSD Staff
A29: 7 | B29: Kaligtasan 2050: Emerging Trends and Futures in Marinduque Safety and Security Scenario | C29: Katrina E. De Mesa Portia RZ. Hermosa | D29: Completed | E29: 11/20/2023 | F29: 4/20/2023 | G29: DLSU D National Conference on Technology and Research for National Development and Sustainability (TReNDS) | H29: DLSU Dasmarinas | I29: National | J29: May 24-26, 2023
